Workbook

Sheet Dashboard
B2: ⚡ QUIZ VIKINGS — SIMULAÇÃO FINANCEIRA 2025
B3: Patrocinadores: WIZARD • FIEBTECH | App: R$20 acesso vitalício
B5: RECEITA BRUTA ANUAL | D5: PATROCÍNIOS TOTAIS | F5: LUCRO LÍQUIDO ANUAL
B6: =Receitas!P5 -> 48270 | D6: =Receitas!P21 -> 31277 | F6: =DRE!P13 -> 39617
B7: RECEITA APP (R$20) | D7: VENDAS DO APP | F7: TICKET MÉDIO
B8: =Pagamentos!P25 -> 36740 | D8: =Pagamentos!P26 -> 1837 | F8: =IFERROR(Pagamentos!P25/Pagamentos!P26,0) -> 20
B10: RESUMO MENSAL
B11: Mês | C11: Receita Bruta | D11: Patrocínios | E11: App (R$20) | F11: Custos | G11: Lucro | H11: Margem %
B12: Jan | C12: =Receitas!C5 -> 3035 | D12: =Receitas!C21 -> 2100 | E12: =Pagamentos!C25 -> 1640 | F12: =Custos!C5 -> 2736 | G12: =C12+E12-F12 -> 1939 | H12: =IFERROR(G12/C12,0) -> 0.63887974
B13: Fev | C13: =Receitas!D5 -> 3180 | D13: =Receitas!D21 -> 2180 | E13: =Pagamentos!D25 -> 1820 | F13: =Custos!D5 -> 2785 | G13: =C13+E13-F13 -> 2215 | H13: =IFERROR(G13/C13,0) -> 0.69654088
B14: Mar | C14: =Receitas!E5 -> 3331 | D14: =Receitas!E21 -> 2262 | E14: =Pagamentos!E25 -> 2020 | F14: =Custos!E5 -> 2835 | G14: =C14+E14-F14 -> 2516 | H14: =IFERROR(G14/C14,0) -> 0.75532873
B15: Abr | C15: =Receitas!F5 -> 3492 | D15: =Receitas!F21 -> 2348 | E15: =Pagamentos!F25 -> 2220 | F15: =Custos!F5 -> 2887 | G15: =C15+E15-F15 -> 2825 | H15: =IFERROR(G15/C15,0) -> 0.80899198
B16: Mai | C16: =Receitas!G5 -> 3667 | D16: =Receitas!G21 -> 2439 | E16: =Pagamentos!G25 -> 2460 | F16: =Custos!G5 -> 2940 | G16: =C16+E16-F16 -> 3187 | H16: =IFERROR(G16/C16,0) -> 0.86910281
B17: Jun | C17: =Receitas!H5 -> 3852 | D17: =Receitas!H21 -> 2533 | E17: =Pagamentos!H25 -> 2720 | F17: =Custos!H5 -> 2995 | G17: =C17+E17-F17 -> 3577 | H17: =IFERROR(G17/C17,0) -> 0.92860852
B18: Jul | C18: =Receitas!I5 -> 4049 | D18: =Receitas!I21 -> 2631 | E18: =Pagamentos!I25 -> 3020 | F18: =Custos!I5 -> 3051 | G18: =C18+E18-F18 -> 4018 | H18: =IFERROR(G18/C18,0) -> 0.99234379
B19: Ago | C19: =Receitas!J5 -> 4257 | D19: =Receitas!J21 -> 2733 | E19: =Pagamentos!J25 -> 3340 | F19: =Custos!J5 -> 3110 | G19: =C19+E19-F19 -> 4487 | H19: =IFERROR(G19/C19,0) -> 1.0540287
B20: Set | C20: =Receitas!K5 -> 4479 | D20: =Receitas!K21 -> 2840 | E20: =Pagamentos!K25 -> 3720 | F20: =Custos!K5 -> 3172 | G20: =C20+E20-F20 -> 5027 | H20: =IFERROR(G20/C20,0) -> 1.1223487
B21: Out | C21: =Receitas!L5 -> 4716 | D21: =Receitas!L21 -> 2952 | E21: =Pagamentos!L25 -> 4120 | F21: =Custos!L5 -> 3237 | G21: =C21+E21-F21 -> 5599 | H21: =IFERROR(G21/C21,0) -> 1.1872349
B22: Nov | C22: =Receitas!M5 -> 4971 | D22: =Receitas!M21 -> 3069 | E22: =Pagamentos!M25 -> 4580 | F22: =Custos!M5 -> 3306 | G22: =C22+E22-F22 -> 6245 | H22: =IFERROR(G22/C22,0) -> 1.2562865
B23: Dez | C23: =Receitas!N5 -> 5241 | D23: =Receitas!N21 -> 3190 | E23: =Pagamentos!N25 -> 5080 | F23: =Custos!N5 -> 3377 | G23: =C23+E23-F23 -> 6944 | H23: =IFERROR(G23/C23,0) -> 1.324938
B24: TOTAL 2025 | C24: =SUM(C12:C23) -> 48270 | D24: =SUM(D12:D23) -> 31277 | E24: =SUM(E12:E23) -> 36740 | F24: =SUM(F12:F23) -> 36431 | G24: =SUM(G12:G23) -> 48579 | H24: =IFERROR(G24/C24,0) -> 1.0064015
B26: PATROCINADORES
B27: 🎓 WIZARD Escola de Idiomas Patrocinador Oficial Quiz Vikings 2025 | E27: 🖥️ FIEBTECH Tecnologia & Inovação Patrocinador Oficial Quiz Vikings 2025

Sheet Receitas
B2: ⚡ QUIZ VIKINGS — RECEITAS MENSAIS 2025
B3: Valores em R$ | Quiz educacional patrocinado por WIZARD & FIEBTECH
B4: Fonte de Receita | C4: Jan | D4: Fev | E4: Mar | F4: Abr | G4: Mai | H4: Jun | I4: Jul | J4: Ago | K4: Set | L4: Out | M4: Nov | N4: Dez | P4: TOTAL ANUAL
B5: RECEITA BRUTA TOTAL | C5: =C11+C15+C21 -> 3035 | D5: =D11+D15+D21 -> 3180 | E5: =E11+E15+E21 -> 3331 | F5: =F11+F15+F21 -> 3492 | G5: =G11+G15+G21 -> 3667 | H5: =H11+H15+H21 -> 3852 | I5: =I11+I15+I21 -> 4049 | J5: =J11+J15+J21 -> 4257 | ... N5: =N11+N15+N21 -> 5241 | P5: =SUM(C5:N5) -> 48270
B6: ── RECEITAS OPERACIONAIS
B7: Assinaturas Premium (R$5,90/mês) | C7: 320 | D7: =ROUND(C7*1.085,0) -> 347 | E7: =ROUND(D7*1.085,0) -> 376 | F7: =ROUND(E7*1.085,0) -> 408 | G7: =ROUND(F7*1.085,0) -> 443 | H7: =ROUND(G7*1.085,0) -> 481 | I7: =ROUND(H7*1.085,0) -> 522 | J7: =ROUND(I7*1.085,0) -> 566 | K7: =ROUND(J7*1.085,0) -> 614 | ... N7: =ROUND(M7*1.085,0) -> 784 | P7: =SUM(C7:N7) -> 6250
B8: Anúncios In-App | C8: 180 | D8: =ROUND(C8*1.065,0) -> 192 | E8: =ROUND(D8*1.065,0) -> 204 | F8: =ROUND(E8*1.065,0) -> 217 | G8: =ROUND(F8*1.065,0) -> 231 | H8: =ROUND(G8*1.065,0) -> 246 | I8: =ROUND(H8*1.065,0) -> 262 | J8: =ROUND(I8*1.065,0) -> 279 | K8: =ROUND(J8*1.065,0) -> 297 | ... N8: =ROUND(M8*1.065,0) -> 359 | P8: =SUM(C8:N8) -> 3120
B9: Venda de Materiais PDF | C9: 95 | D9: =ROUND(C9*1.04,0) -> 99 | E9: =ROUND(D9*1.04,0) -> 103 | F9: =ROUND(E9*1.04,0) -> 107 | G9: =ROUND(F9*1.04,0) -> 111 | H9: =ROUND(G9*1.04,0) -> 115 | I9: =ROUND(H9*1.04,0) -> 120 | J9: =ROUND(I9*1.04,0) -> 125 | K9: =ROUND(J9*1.04,0) -> 130 | ... N9: =ROUND(M9*1.04,0) -> 146 | P9: =SUM(C9:N9) -> 1426
B10: Torneios Pagos (entrada R$2) | C10: 140 | D10: =ROUND(C10*1.12,0) -> 157 | E10: =ROUND(D10*1.12,0) -> 176 | F10: =ROUND(E10*1.12,0) -> 197 | G10: =ROUND(F10*1.12,0) -> 221 | H10: =ROUND(G10*1.12,0) -> 248 | I10: =ROUND(H10*1.12,0) -> 278 | J10: =ROUND(I10*1.12,0) -> 311 | K10: =ROUND(J10*1.12,0) -> 348 | ... N10: =ROUND(M10*1.12,0) -> 489 | P10: =SUM(C10:N10) -> 3392
B11: Subtotal Operacional | C11: =SUM(C7:C10) -> 735 | D11: =SUM(D7:D10) -> 795 | E11: =SUM(E7:E10) -> 859 | F11: =SUM(F7:F10) -> 929 | G11: =SUM(G7:G10) -> 1006 | H11: =SUM(H7:H10) -> 1090 | I11: =SUM(I7:I10) -> 1182 | J11: =SUM(J7:J10) -> 1281 | ... N11: =SUM(N7:N10) -> 1778 | P11: =SUM(C11:N11) -> 14188
B12: ── OUTRAS RECEITAS
B13: Licenciamento de Conteúdo | C13: 120 | D13: =ROUND(C13*1.02,0) -> 122 | E13: =ROUND(D13*1.02,0) -> 124 | F13: =ROUND(E13*1.02,0) -> 126 | G13: =ROUND(F13*1.02,0) -> 129 | H13: =ROUND(G13*1.02,0) -> 132 | I13: =ROUND(H13*1.02,0) -> 135 | J13: =ROUND(I13*1.02,0) -> 138 | K13: =ROUND(J13*1.02,0) -> 141 | ... N13: =ROUND(M13*1.02,0) -> 150 | P13: =SUM(C13:N13) -> 1608
B14: Parcerias Educacionais | C14: 80 | D14: =ROUND(C14*1.04,0) -> 83 | E14: =ROUND(D14*1.04,0) -> 86 | F14: =ROUND(E14*1.04,0) -> 89 | G14: =ROUND(F14*1.04,0) -> 93 | H14: =ROUND(G14*1.04,0) -> 97 | I14: =ROUND(H14*1.04,0) -> 101 | J14: =ROUND(I14*1.04,0) -> 105 | K14: =ROUND(J14*1.04,0) -> 109 | ... N14: =ROUND(M14*1.04,0) -> 123 | P14: =SUM(C14:N14) -> 1197
B15: Subtotal Outras | C15: =SUM(C13:C14) -> 200 | D15: =SUM(D13:D14) -> 205 | E15: =SUM(E13:E14) -> 210 | F15: =SUM(F13:F14) -> 215 | G15: =SUM(G13:G14) -> 222 | H15: =SUM(H13:H14) -> 229 | I15: =SUM(I13:I14) -> 236 | J15: =SUM(J13:J14) -> 243 | ... N15: =SUM(N13:N14) -> 273 | P15: =SUM(C15:N15) -> 2805
B16: ── PATROCÍNIOS
B17: Wizard — Patrocínio Mensal | C17: 850 | D17: =ROUND(C17*1.03,0) -> 876 | E17: =ROUND(D17*1.03,0) -> 902 | F17: =ROUND(E17*1.03,0) -> 929 | G17: =ROUND(F17*1.03,0) -> 957 | H17: =ROUND(G17*1.03,0) -> 986 | I17: =ROUND(H17*1.03,0) -> 1016 | J17: =ROUND(I17*1.03,0) -> 1046 | K17: =ROUND(J17*1.03,0) -> 1077 | ... N17: =ROUND(M17*1.03,0) -> 1176 | P17: =SUM(C17:N17) -> 12066
B18: Wizard — Bônus por Desempenho | C18: 200 | D18: =ROUND(C18*1.05,0) -> 210 | E18: =ROUND(D18*1.05,0) -> 221 | F18: =ROUND(E18*1.05,0) -> 232 | G18: =ROUND(F18*1.05,0) -> 244 | H18: =ROUND(G18*1.05,0) -> 256 | I18: =ROUND(H18*1.05,0) -> 269 | J18: =ROUND(I18*1.05,0) -> 282 | K18: =ROUND(J18*1.05,0) -> 296 | ... N18: =ROUND(M18*1.05,0) -> 343 | P18: =SUM(C18:N18) -> 3191
B19: FIEBTECH — Patrocínio Mensal | C19: 750 | D19: =ROUND(C19*1.03,0) -> 773 | E19: =ROUND(D19*1.03,0) -> 796 | F19: =ROUND(E19*1.03,0) -> 820 | G19: =ROUND(F19*1.03,0) -> 845 | H19: =ROUND(G19*1.03,0) -> 870 | I19: =ROUND(H19*1.03,0) -> 896 | J19: =ROUND(I19*1.03,0) -> 923 | K19: =ROUND(J19*1.03,0) -> 951 | ... N19: =ROUND(M19*1.03,0) -> 1039 | P19: =SUM(C19:N19) -> 10652
B20: FIEBTECH — Ativações Digitais | C20: 300 | D20: =ROUND(C20*1.07,0) -> 321 | E20: =ROUND(D20*1.07,0) -> 343 | F20: =ROUND(E20*1.07,0) -> 367 | G20: =ROUND(F20*1.07,0) -> 393 | H20: =ROUND(G20*1.07,0) -> 421 | I20: =ROUND(H20*1.07,0) -> 450 | J20: =ROUND(I20*1.07,0) -> 482 | K20: =ROUND(J20*1.07,0) -> 516 | ... N20: =ROUND(M20*1.07,0) -> 632 | P20: =SUM(C20:N20) -> 5368
B21: Subtotal Patrocínios | C21: =SUM(C17:C20) -> 2100 | D21: =SUM(D17:D20) -> 2180 | E21: =SUM(E17:E20) -> 2262 | F21: =SUM(F17:F20) -> 2348 | G21: =SUM(G17:G20) -> 2439 | H21: =SUM(H17:H20) -> 2533 | I21: =SUM(I17:I20) -> 2631 | J21: =SUM(J17:J20) -> 2733 | ... N21: =SUM(N17:N20) -> 3190 | P21: =SUM(C21:N21) -> 31277

Sheet Custos
B2: ⚡ QUIZ VIKINGS — CUSTOS E DESPESAS 2025
B3: Valores em R$ | Custos operacionais de plataforma digital educacional
B4: Item de Custo | C4: Jan | D4: Fev | E4: Mar | F4: Abr | G4: Mai | H4: Jun | I4: Jul | J4: Ago | K4: Set | L4: Out | M4: Nov | N4: Dez | P4: TOTAL ANUAL
B5: TOTAL DE CUSTOS | C5: =C10+C15+C20+C26 -> 2736 | D5: =D10+D15+D20+D26 -> 2785 | E5: =E10+E15+E20+E26 -> 2835 | F5: =F10+F15+F20+F26 -> 2887 | G5: =G10+G15+G20+G26 -> 2940 | H5: =H10+H15+H20+H26 -> 2995 | I5: =I10+I15+I20+I26 -> 3051 | J5: =J10+J15+J20+J26 -> 3110 | ... N5: =N10+N15+N20+N26 -> 3377 | P5: =SUM(C5:N5) -> 36431
B6: ── INFRAESTRUTURA
B7: Hospedagem / Cloud | C7: 280 | D7: =ROUND(C7*1.02,0) -> 286 | E7: =ROUND(D7*1.02,0) -> 292 | F7: =ROUND(E7*1.02,0) -> 298 | G7: =ROUND(F7*1.02,0) -> 304 | H7: =ROUND(G7*1.02,0) -> 310 | I7: =ROUND(H7*1.02,0) -> 316 | J7: =ROUND(I7*1.02,0) -> 322 | K7: =ROUND(J7*1.02,0) -> 328 | ... N7: =ROUND(M7*1.02,0) -> 349 | P7: =SUM(C7:N7) -> 3762
B8: Domínio e SSL | C8: 25 | D8: 25 | E8: 25 | F8: 25 | G8: 25 | H8: 25 | I8: 25 | J8: 25 | K8: 25 | L8: 25 | M8: 25 | N8: 25 | P8: =SUM(C8:N8) -> 300
B9: CDN e Armazenamento | C9: 90 | D9: =ROUND(C9*1.03,0) -> 93 | E9: =ROUND(D9*1.03,0) -> 96 | F9: =ROUND(E9*1.03,0) -> 99 | G9: =ROUND(F9*1.03,0) -> 102 | H9: =ROUND(G9*1.03,0) -> 105 | I9: =ROUND(H9*1.03,0) -> 108 | J9: =ROUND(I9*1.03,0) -> 111 | K9: =ROUND(J9*1.03,0) -> 114 | ... N9: =ROUND(M9*1.03,0) -> 125 | P9: =SUM(C9:N9) -> 1281
B10: Subtotal Infra | C10: =SUM(C7:C9) -> 395 | D10: =SUM(D7:D9) -> 404 | E10: =SUM(E7:E9) -> 413 | F10: =SUM(F7:F9) -> 422 | G10: =SUM(G7:G9) -> 431 | H10: =SUM(H7:H9) -> 440 | I10: =SUM(I7:I9) -> 449 | J10: =SUM(J7:J9) -> 458 | ... N10: =SUM(N7:N9) -> 499 | P10: =SUM(C10:N10) -> 5343
B11: ── DESENVOLVIMENTO
B12: Desenvolvedor Freelancer | C12: 600 | D12: 600 | E12: 600 | F12: 600 | G12: 600 | H12: 600 | I12: 600 | J12: 600 | K12: 600 | L12: 600 | M12: 600 | N12: 600 | P12: =SUM(C12:N12) -> 7200
B13: Designer UI/UX | C13: 400 | D13: 400 | E13: 400 | F13: 400 | G13: 400 | H13: 400 | I13: 400 | J13: 400 | K13: 400 | L13: 400 | M13: 400 | N13: 400 | P13: =SUM(C13:N13) -> 4800
B14: Ferramentas Dev | C14: 80 | D14: =ROUND(C14*1.01,0) -> 81 | E14: =ROUND(D14*1.01,0) -> 82 | F14: =ROUND(E14*1.01,0) -> 83 | G14: =ROUND(F14*1.01,0) -> 84 | H14: =ROUND(G14*1.01,0) -> 85 | I14: =ROUND(H14*1.01,0) -> 86 | J14: =ROUND(I14*1.01,0) -> 87 | K14: =ROUND(J14*1.01,0) -> 88 | ... N14: =ROUND(M14*1.01,0) -> 91 | P14: =SUM(C14:N14) -> 1026
B15: Subtotal Dev | C15: =SUM(C12:C14) -> 1080 | D15: =SUM(D12:D14) -> 1081 | E15: =SUM(E12:E14) -> 1082 | F15: =SUM(F12:F14) -> 1083 | G15: =SUM(G12:G14) -> 1084 | H15: =SUM(H12:H14) -> 1085 | I15: =SUM(I12:I14) -> 1086 | J15: =SUM(J12:J14) -> 1087 | ... N15: =SUM(N12:N14) -> 1091 | P15: =SUM(C15:N15) -> 13026
B16: ── MARKETING
B17: Anúncios Google/Meta | C17: 350 | D17: =ROUND(C17*1.05,0) -> 368 | E17: =ROUND(D17*1.05,0) -> 386 | F17: =ROUND(E17*1.05,0) -> 405 | G17: =ROUND(F17*1.05,0) -> 425 | H17: =ROUND(G17*1.05,0) -> 446 | I17: =ROUND(H17*1.05,0) -> 468 | J17: =ROUND(I17*1.05,0) -> 491 | K17: =ROUND(J17*1.05,0) -> 516 | ... N17: =ROUND(M17*1.05,0) -> 597 | P17: =SUM(C17:N17) -> 5563
B18: Marketing de Conteúdo | C18: 200 | D18: =ROUND(C18*1.04,0) -> 208 | E18: =ROUND(D18*1.04,0) -> 216 | F18: =ROUND(E18*1.04,0) -> 225 | G18: =ROUND(F18*1.04,0) -> 234 | H18: =ROUND(G18*1.04,0) -> 243 | I18: =ROUND(H18*1.04,0) -> 253 | J18: =ROUND(I18*1.04,0) -> 263 | K18: =ROUND(J18*1.04,0) -> 274 | ... N18: =ROUND(M18*1.04,0) -> 308 | P18: =SUM(C18:N18) -> 3005
B19: Influenciadores Educacionais | C19: 150 | D19: =ROUND(C19*1.03,0) -> 155 | E19: =ROUND(D19*1.03,0) -> 160 | F19: =ROUND(E19*1.03,0) -> 165 | G19: =ROUND(F19*1.03,0) -> 170 | H19: =ROUND(G19*1.03,0) -> 175 | I19: =ROUND(H19*1.03,0) -> 180 | J19: =ROUND(I19*1.03,0) -> 185 | K19: =ROUND(J19*1.03,0) -> 191 | ... N19: =ROUND(M19*1.03,0) -> 209 | P19: =SUM(C19:N19) -> 2140
B20: Subtotal Marketing | C20: =SUM(C17:C19) -> 700 | D20: =SUM(D17:D19) -> 731 | E20: =SUM(E17:E19) -> 762 | F20: =SUM(F17:F19) -> 795 | G20: =SUM(G17:G19) -> 829 | H20: =SUM(H17:H19) -> 864 | I20: =SUM(I17:I19) -> 901 | J20: =SUM(J17:J19) -> 939 | ... N20: =SUM(N17:N19) -> 1114 | P20: =SUM(C20:N20) -> 10708
B21: ── OPERACIONAL
B22: Atendimento ao Cliente | C22: 150 | D22: =ROUND(C22*1.02,0) -> 153 | E22: =ROUND(D22*1.02,0) -> 156 | F22: =ROUND(E22*1.02,0) -> 159 | G22: =ROUND(F22*1.02,0) -> 162 | H22: =ROUND(G22*1.02,0) -> 165 | I22: =ROUND(H22*1.02,0) -> 168 | J22: =ROUND(I22*1.02,0) -> 171 | K22: =ROUND(J22*1.02,0) -> 174 | ... N22: =ROUND(M22*1.02,0) -> 185 | P22: =SUM(C22:N22) -> 2001
B23: Ferramentas SaaS | C23: 120 | D23: =ROUND(C23*1.01,0) -> 121 | E23: =ROUND(D23*1.01,0) -> 122 | F23: =ROUND(E23*1.01,0) -> 123 | G23: =ROUND(F23*1.01,0) -> 124 | H23: =ROUND(G23*1.01,0) -> 125 | I23: =ROUND(H23*1.01,0) -> 126 | J23: =ROUND(I23*1.01,0) -> 127 | K23: =ROUND(J23*1.01,0) -> 128 | ... N23: =ROUND(M23*1.01,0) -> 131 | P23: =SUM(C23:N23) -> 1506
B24: Taxas de Pagamento (3%) | C24: =ROUND(Receitas!C5*0.03,0) -> 91 | D24: =ROUND(Receitas!D5*0.03,0) -> 95 | E24: =ROUND(Receitas!E5*0.03,0) -> 100 | F24: =ROUND(Receitas!F5*0.03,0) -> 105 | G24: =ROUND(Receitas!G5*0.03,0) -> 110 | H24: =ROUND(Receitas!H5*0.03,0) -> 116 | I24: =ROUND(Receitas!I5*0.03,0) -> 121 | J24: =ROUND(Receitas!J5*0.03,0) -> 128 | ... N24: =ROUND(Receitas!N5*0.03,0) -> 157 | P24: =SUM(C24:N24) -> 1447
B25: Contador / Jurídico | C25: 200 | D25: 200 | E25: 200 | F25: 200 | G25: 200 | H25: 200 | I25: 200 | J25: 200 | K25: 200 | L25: 200 | M25: 200 | N25: 200 | P25: =SUM(C25:N25) -> 2400
B26: Subtotal Operacional | C26: =SUM(C22:C25) -> 561 | D26: =SUM(D22:D25) -> 569 | E26: =SUM(E22:E25) -> 578 | F26: =SUM(F22:F25) -> 587 | G26: =SUM(G22:G25) -> 596 | H26: =SUM(H22:H25) -> 606 | I26: =SUM(I22:I25) -> 615 | J26: =SUM(J22:J25) -> 626 | ... N26: =SUM(N22:N25) -> 673 | P26: =SUM(C26:N26) -> 7354

Sheet DRE
B2: ⚡ QUIZ VIKINGS — DRE 2025 | Inclui Receita App R$20
B3: Demonstrativo de Resultado | WIZARD & FIEBTECH Patrocinadores
B4: Indicador | C4: Jan | D4: Fev | E4: Mar | F4: Abr | G4: Mai | H4: Jun | I4: Jul | J4: Ago | K4: Set | L4: Out | M4: Nov | N4: Dez | P4: TOTAL ANUAL
B5: (+) Receita Operacional | C5: =Receitas!C5 -> 3035 | D5: =Receitas!D5 -> 3180 | E5: =Receitas!E5 -> 3331 | F5: =Receitas!F5 -> 3492 | G5: =Receitas!G5 -> 3667 | H5: =Receitas!H5 -> 3852 | I5: =Receitas!I5 -> 4049 | J5: =Receitas!J5 -> 4257 | ... N5: =Receitas!N5 -> 5241 | P5: =SUM(C5:N5) -> 48270
B6: (+) Receita App (R$20) | C6: =Pagamentos!C25 -> 1640 | D6: =Pagamentos!D25 -> 1820 | E6: =Pagamentos!E25 -> 2020 | F6: =Pagamentos!F25 -> 2220 | G6: =Pagamentos!G25 -> 2460 | H6: =Pagamentos!H25 -> 2720 | I6: =Pagamentos!I25 -> 3020 | J6: =Pagamentos!J25 -> 3340 | ... N6: =Pagamentos!N25 -> 5080 | P6: =SUM(C6:N6) -> 36740
B7: (+) Receita Total | C7: =C5+C6 -> 4675 | D7: =D5+D6 -> 5000 | E7: =E5+E6 -> 5351 | F7: =F5+F6 -> 5712 | G7: =G5+G6 -> 6127 | H7: =H5+H6 -> 6572 | I7: =I5+I6 -> 7069 | J7: =J5+J6 -> 7597 | ... N7: =N5+N6 -> 10321 | P7: =SUM(C7:N7) -> 85010
B8: (-) Impostos s/ Receita (8%) | C8: =ROUND(C7*-0.08,0) -> -374 | D8: =ROUND(D7*-0.08,0) -> -400 | E8: =ROUND(E7*-0.08,0) -> -428 | F8: =ROUND(F7*-0.08,0) -> -457 | G8: =ROUND(G7*-0.08,0) -> -490 | H8: =ROUND(H7*-0.08,0) -> -526 | I8: =ROUND(I7*-0.08,0) -> -566 | J8: =ROUND(J7*-0.08,0) -> -608 | ... N8: =ROUND(N7*-0.08,0) -> -826 | P8: =SUM(C8:N8) -> -6802
B9: (=) Receita Liquida | C9: =C7+C8 -> 4301 | D9: =D7+D8 -> 4600 | E9: =E7+E8 -> 4923 | F9: =F7+F8 -> 5255 | G9: =G7+G8 -> 5637 | H9: =H7+H8 -> 6046 | I9: =I7+I8 -> 6503 | J9: =J7+J8 -> 6989 | ... N9: =N7+N8 -> 9495 | P9: =SUM(C9:N9) -> 78208
B10: (-) Custos Operacionais | C10: =Custos!C5*-1 -> -2736 | D10: =Custos!D5*-1 -> -2785 | E10: =Custos!E5*-1 -> -2835 | F10: =Custos!F5*-1 -> -2887 | G10: =Custos!G5*-1 -> -2940 | H10: =Custos!H5*-1 -> -2995 | I10: =Custos!I5*-1 -> -3051 | J10: =Custos!J5*-1 -> -3110 | ... N10: =Custos!N5*-1 -> -3377 | P10: =SUM(C10:N10) -> -36431
B11: (=) EBITDA | C11: =C9+C10 -> 1565 | D11: =D9+D10 -> 1815 | E11: =E9+E10 -> 2088 | F11: =F9+F10 -> 2368 | G11: =G9+G10 -> 2697 | H11: =H9+H10 -> 3051 | I11: =I9+I10 -> 3452 | J11: =J9+J10 -> 3879 | ... N11: =N9+N10 -> 6118 | P11: =SUM(C11:N11) -> 41777
B12: (-) Depreciacao estimada | C12: =-180 -> -180 | D12: =-180 -> -180 | E12: =-180 -> -180 | F12: =-180 -> -180 | G12: =-180 -> -180 | H12: =-180 -> -180 | I12: =-180 -> -180 | J12: =-180 -> -180 | ... N12: =-180 -> -180 | P12: =SUM(C12:N12) -> -2160
B13: (=) LUCRO LIQUIDO | C13: =C11+C12 -> 1385 | D13: =D11+D12 -> 1635 | E13: =E11+E12 -> 1908 | F13: =F11+F12 -> 2188 | G13: =G11+G12 -> 2517 | H13: =H11+H12 -> 2871 | I13: =I11+I12 -> 3272 | J13: =J11+J12 -> 3699 | ... N13: =N11+N12 -> 5938 | P13: =SUM(C13:N13) -> 39617
B14: ─────────────────────────
B15: Margem Bruta (%) | C15: =IFERROR(C9/C7,0) -> 0.92 | D15: =IFERROR(D9/D7,0) -> 0.92 | E15: =IFERROR(E9/E7,0) -> 0.92001495 | F15: =IFERROR(F9/F7,0) -> 0.919993 | G15: =IFERROR(G9/G7,0) -> 0.92002611 | H15: =IFERROR(H9/H7,0) -> 0.91996348 | I15: =IFERROR(I9/I7,0) -> 0.9199321 | J15: =IFERROR(J9/J7,0) -> 0.91996841 | ... N15: =IFERROR(N9/N7,0) -> 0.919969 | P15: =AVERAGE(C15:N15) -> 0.91998767
B16: Margem EBITDA (%) | C16: =IFERROR(C11/C7,0) -> 0.33475936 | D16: =IFERROR(D11/D7,0) -> 0.363 | E16: =IFERROR(E11/E7,0) -> 0.39020744 | F16: =IFERROR(F11/F7,0) -> 0.41456583 | G16: =IFERROR(G11/G7,0) -> 0.4401828 | H16: =IFERROR(H11/H7,0) -> 0.46424224 | I16: =IFERROR(I11/I7,0) -> 0.48832933 | J16: =IFERROR(J11/J7,0) -> 0.51059629 | ... N16: =IFERROR(N11/N7,0) -> 0.59277202 | P16: =AVERAGE(C16:N16) -> 0.47160666
B17: Margem Liquida (%) | C17: =IFERROR(C13/C7,0) -> 0.29625668 | D17: =IFERROR(D13/D7,0) -> 0.327 | E17: =IFERROR(E13/E7,0) -> 0.35656887 | F17: =IFERROR(F13/F7,0) -> 0.38305322 | G17: =IFERROR(G13/G7,0) -> 0.41080464 | H17: =IFERROR(H13/H7,0) -> 0.43685332 | I17: =IFERROR(I13/I7,0) -> 0.46286603 | J17: =IFERROR(J13/J7,0) -> 0.48690272 | ... N17: =IFERROR(N13/N7,0) -> 0.57533185 | P17: =AVERAGE(C17:N17) -> 0.44459088
B18: ─────────────────────────
B19: Receita de Patrocinios | C19: =Receitas!C21 -> 2100 | D19: =Receitas!D21 -> 2180 | E19: =Receitas!E21 -> 2262 | F19: =Receitas!F21 -> 2348 | G19: =Receitas!G21 -> 2439 | H19: =Receitas!H21 -> 2533 | I19: =Receitas!I21 -> 2631 | J19: =Receitas!J21 -> 2733 | ... N19: =Receitas!N21 -> 3190 | P19: =SUM(C19:N19) -> 31277
B20: Receita do App (R$20) | C20: =Pagamentos!C25 -> 1640 | D20: =Pagamentos!D25 -> 1820 | E20: =Pagamentos!E25 -> 2020 | F20: =Pagamentos!F25 -> 2220 | G20: =Pagamentos!G25 -> 2460 | H20: =Pagamentos!H25 -> 2720 | I20: =Pagamentos!I25 -> 3020 | J20: =Pagamentos!J25 -> 3340 | ... N20: =Pagamentos!N25 -> 5080 | P20: =SUM(C20:N20) -> 36740
B21: % Patrocinios / Receita | C21: =IFERROR(Receitas!C21/C7,0) -> 0.44919786 | D21: =IFERROR(Receitas!D21/D7,0) -> 0.436 | E21: =IFERROR(Receitas!E21/E7,0) -> 0.42272472 | F21: =IFERROR(Receitas!F21/F7,0) -> 0.41106443 | G21: =IFERROR(Receitas!G21/G7,0) -> 0.3980741 | H21: =IFERROR(Receitas!H21/H7,0) -> 0.38542301 | I21: =IFERROR(Receitas!I21/I7,0) -> 0.37218843 | J21: =IFERROR(Receitas!J21/J7,0) -> 0.35974727 | ... N21: =IFERROR(Receitas!N21/N7,0) -> 0.30907858 | P21: =AVERAGE(C21:N21) -> 0.37877479
B22: % App / Receita | C22: =IFERROR(Pagamentos!C25/C7,0) -> 0.35080214 | D22: =IFERROR(Pagamentos!D25/D7,0) -> 0.364 | E22: =IFERROR(Pagamentos!E25/E7,0) -> 0.37749953 | F22: =IFERROR(Pagamentos!F25/F7,0) -> 0.38865546 | G22: =IFERROR(Pagamentos!G25/G7,0) -> 0.40150155 | H22: =IFERROR(Pagamentos!H25/H7,0) -> 0.41387705 | I22: =IFERROR(Pagamentos!I25/I7,0) -> 0.42721743 | J22: =IFERROR(Pagamentos!J25/J7,0) -> 0.43964723 | ... N22: =IFERROR(Pagamentos!N25/N7,0) -> 0.49220037 | P22: =AVERAGE(C22:N22) -> 0.42124333

Sheet Pagamentos
B2: ⚡ QUIZ VIKINGS — RECEITA DO APP (R$20 / ACESSO VITALICIO)
B3: Projecao de vendas: R$20 por usuario | PIX / Cartao Credito / Cartao Debito
B4: 💳 PRODUTO: Quiz Vikings App • PRECO: R$20,00 • MODELO: Pagamento unico vitalicio • FORMAS: PIX / Cartao Credito / Debito
B5: Metrica | C5: Jan | D5: Fev | E5: Mar | F5: Abr | G5: Mai | H5: Jun | I5: Jul | J5: Ago | K5: Set | L5: Out | M5: Nov | N5: Dez | P5: TOTAL ANUAL
B6: RECEITA BRUTA APP | C6: =C16 -> 1640 | D6: =D16 -> 1820 | E6: =E16 -> 2020 | F6: =F16 -> 2220 | G6: =G16 -> 2460 | H6: =H16 -> 2720 | I6: =I16 -> 3020 | J6: =J16 -> 3340 | ... N6: =N16 -> 5080 | P6: =SUM(C6:N6) -> 36740
B7: ── VENDAS POR CANAL
B8: Vendas via PIX | C8: 42 | D8: =ROUND(C8*1.12,0) -> 47 | E8: =ROUND(D8*1.12,0) -> 53 | F8: =ROUND(E8*1.12,0) -> 59 | G8: =ROUND(F8*1.12,0) -> 66 | H8: =ROUND(G8*1.12,0) -> 74 | I8: =ROUND(H8*1.12,0) -> 83 | J8: =ROUND(I8*1.12,0) -> 93 | K8: =ROUND(J8*1.12,0) -> 104 | ... N8: =ROUND(M8*1.12,0) -> 146 | P8: =SUM(C8:N8) -> 1013
B9: Vendas via Cartao Credito | C9: 28 | D9: =ROUND(C9*1.1,0) -> 31 | E9: =ROUND(D9*1.1,0) -> 34 | F9: =ROUND(E9*1.1,0) -> 37 | G9: =ROUND(F9*1.1,0) -> 41 | H9: =ROUND(G9*1.1,0) -> 45 | I9: =ROUND(H9*1.1,0) -> 50 | J9: =ROUND(I9*1.1,0) -> 55 | K9: =ROUND(J9*1.1,0) -> 61 | ... N9: =ROUND(M9*1.1,0) -> 81 | P9: =SUM(C9:N9) -> 604
B10: Vendas via Cartao Debito | C10: 12 | D10: =ROUND(C10*1.08,0) -> 13 | E10: =ROUND(D10*1.08,0) -> 14 | F10: =ROUND(E10*1.08,0) -> 15 | G10: =ROUND(F10*1.08,0) -> 16 | H10: =ROUND(G10*1.08,0) -> 17 | I10: =ROUND(H10*1.08,0) -> 18 | J10: =ROUND(I10*1.08,0) -> 19 | K10: =ROUND(J10*1.08,0) -> 21 | ... N10: =ROUND(M10*1.08,0) -> 27 | P10: =SUM(C10:N10) -> 220
B11: Subtotal Unidades | C11: =SUM(C8:C10) -> 82 | D11: =SUM(D8:D10) -> 91 | E11: =SUM(E8:E10) -> 101 | F11: =SUM(F8:F10) -> 111 | G11: =SUM(G8:G10) -> 123 | H11: =SUM(H8:H10) -> 136 | I11: =SUM(I8:I10) -> 151 | J11: =SUM(J8:J10) -> 167 | ... N11: =SUM(N8:N10) -> 254 | P11: =SUM(C11:N11) -> 1837
B12: ── RECEITA POR CANAL (R$)
B13: Receita PIX | C13: =C8*20 -> 840 | D13: =D8*20 -> 940 | E13: =E8*20 -> 1060 | F13: =F8*20 -> 1180 | G13: =G8*20 -> 1320 | H13: =H8*20 -> 1480 | I13: =I8*20 -> 1660 | J13: =J8*20 -> 1860 | ... N13: =N8*20 -> 2920 | P13: =SUM(C13:N13) -> 20260
B14: Receita Cartao Credito | C14: =C9*20 -> 560 | D14: =D9*20 -> 620 | E14: =E9*20 -> 680 | F14: =F9*20 -> 740 | G14: =G9*20 -> 820 | H14: =H9*20 -> 900 | I14: =I9*20 -> 1000 | J14: =J9*20 -> 1100 | ... N14: =N9*20 -> 1620 | P14: =SUM(C14:N14) -> 12080
B15: Receita Cartao Debito | C15: =C10*20 -> 240 | D15: =D10*20 -> 260 | E15: =E10*20 -> 280 | F15: =F10*20 -> 300 | G15: =G10*20 -> 320 | H15: =H10*20 -> 340 | I15: =I10*20 -> 360 | J15: =J10*20 -> 380 | ... N15: =N10*20 -> 540 | P15: =SUM(C15:N15) -> 4400
B16: Subtotal Receita Bruta | C16: =SUM(C13:C15) -> 1640 | D16: =SUM(D13:D15) -> 1820 | E16: =SUM(E13:E15) -> 2020 | F16: =SUM(F13:F15) -> 2220 | G16: =SUM(G13:G15) -> 2460 | H16: =SUM(H13:H15) -> 2720 | I16: =SUM(I13:I15) -> 3020 | J16: =SUM(J13:J15) -> 3340 | ... N16: =SUM(N13:N15) -> 5080 | P16: =SUM(C16:N16) -> 36740
B17: ── CUSTOS DE TRANSACAO
B18: Taxa PIX (0%) | C18: 0 | D18: 0 | E18: 0 | F18: 0 | G18: 0 | H18: 0 | I18: 0 | J18: 0 | K18: 0 | L18: 0 | M18: 0 | N18: 0 | P18: =SUM(C18:N18) -> 0
B19: Taxa Cartao Credito (-3,5%) | C19: =ROUND(C14*-0.035,0) -> -20 | D19: =ROUND(D14*-0.035,0) -> -22 | E19: =ROUND(E14*-0.035,0) -> -24 | F19: =ROUND(F14*-0.035,0) -> -26 | G19: =ROUND(G14*-0.035,0) -> -29 | H19: =ROUND(H14*-0.035,0) -> -32 | I19: =ROUND(I14*-0.035,0) -> -35 | J19: =ROUND(J14*-0.035,0) -> -39 | ... N19: =ROUND(N14*-0.035,0) -> -57 | P19: =SUM(C19:N19) -> -426
B20: Taxa Cartao Debito (-1,5%) | C20: =ROUND(C15*-0.015,0) -> -4 | D20: =ROUND(D15*-0.015,0) -> -4 | E20: =ROUND(E15*-0.015,0) -> -4 | F20: =ROUND(F15*-0.015,0) -> -5 | G20: =ROUND(G15*-0.015,0) -> -5 | H20: =ROUND(H15*-0.015,0) -> -5 | I20: =ROUND(I15*-0.015,0) -> -5 | J20: =ROUND(J15*-0.015,0) -> -6 | ... N20: =ROUND(N15*-0.015,0) -> -8 | P20: =SUM(C20:N20) -> -67
B21: Subtotal Taxas | C21: =SUM(C18:C20) -> -24 | D21: =SUM(D18:D20) -> -26 | E21: =SUM(E18:E20) -> -28 | F21: =SUM(F18:F20) -> -31 | G21: =SUM(G18:G20) -> -34 | H21: =SUM(H18:H20) -> -37 | I21: =SUM(I18:I20) -> -40 | J21: =SUM(J18:J20) -> -45 | ... N21: =SUM(N18:N20) -> -65 | P21: =SUM(C21:N21) -> -493
B22: RECEITA LIQUIDA APP | C22: =C16+C21 -> 1616 | D22: =D16+D21 -> 1794 | E22: =E16+E21 -> 1992 | F22: =F16+F21 -> 2189 | G22: =G16+G21 -> 2426 | H22: =H16+H21 -> 2683 | I22: =I16+I21 -> 2980 | J22: =J16+J21 -> 3295 | ... N22: =N16+N21 -> 5015 | P22: =SUM(C22:N22) -> 36247
B24: RESUMO PARA DASHBOARD
B25: Receita Mensal App (R$) | C25: =C6 -> 1640 | D25: =D6 -> 1820 | E25: =E6 -> 2020 | F25: =F6 -> 2220 | G25: =G6 -> 2460 | H25: =H6 -> 2720 | I25: =I6 -> 3020 | J25: =J6 -> 3340 | ... N25: =N6 -> 5080 | P25: =SUM(C25:N25) -> 36740
B26: Unidades Vendidas (mensal) | C26: =C11 -> 82 | D26: =D11 -> 91 | E26: =E11 -> 101 | F26: =F11 -> 111 | G26: =G11 -> 123 | H26: =H11 -> 136 | I26: =I11 -> 151 | J26: =J11 -> 167 | ... N26: =N11 -> 254 | P26: =SUM(C26:N26) -> 1837

Sheet Patrocinadores
B2: ⚡ QUIZ VIKINGS — CONTRATOS DE PATROCINIO 2025
B3: WIZARD Escola de Idiomas & FIEBTECH Tecnologia e Inovacao
B5: 🎓 WIZARD — Escola de Idiomas
B6: Tipo de Patrocinio | C6: Naming Rights + Visibilidade Digital Completa
B7: Valor Mensal Fixo | C7: R$ 850,00 / mes
B8: Bonus por Metas | C8: R$ 200,00 / mes (engajamento atingido)
B9: Duracao | C9: 12 meses — Janeiro a Dezembro / 2025
B10: Entregaveis | C10: Logo em todas as telas • 1 quiz idiomas/mes • Relatorio mensal
B11: Investimento Total 2025 | C11: R$ 12.600,00 + bonus variavel
B13: PROJECAO MENSAL — 🎓 WIZARD
B14: Mes | C14: Fixo (R$) | D14: Variavel (R$) | E14: Total (R$) | F14: Usuarios | G14: Impressoes | H14: ROI Est.
B15: Jan | C15: 850 | D15: 200 | E15: 1050 | F15: 1200 | G15: 4200 | H15: 8.5x
B16: Fev | C16: 850 | D16: 210 | E16: 1060 | F16: 1272 | G16: 4452 | H16: 8.8x
B17: Mar | C17: 850 | D17: 220 | E17: 1070 | F17: 1348 | G17: 4719 | H17: 9.1x
B18: Abr | C18: 850 | D18: 231 | E18: 1081 | F18: 1429 | G18: 5002 | H18: 9.4x
B19: Mai | C19: 850 | D19: 243 | E19: 1093 | F19: 1514 | G19: 5302 | H19: 9.7x
B20: Jun | C20: 850 | D20: 255 | E20: 1105 | F20: 1605 | G20: 5620 | H20: 10.0x
B21: Jul | C21: 850 | D21: 268 | E21: 1118 | F21: 1702 | G21: 5957 | H21: 10.3x
B22: Ago | C22: 850 | D22: 281 | E22: 1131 | F22: 1804 | G22: 6315 | H22: 10.6x
B23: Set | C23: 850 | D23: 295 | E23: 1145 | F23: 1912 | G23: 6694 | H23: 10.9x
B24: Out | C24: 850 | D24: 310 | E24: 1160 | F24: 2027 | G24: 7095 | H24: 11.2x
B25: Nov | C25: 850 | D25: 325 | E25: 1175 | F25: 2149 | G25: 7521 | H25: 11.5x
B26: Dez | C26: 850 | D26: 342 | E26: 1192 | F26: 2277 | G26: 7972 | H26: 11.8x
B29: 🖥️ FIEBTECH — Tecnologia & Inovacao
B30: Tipo de Patrocinio | C30: Tech Partner Premium + Branding Interativo
B31: Valor Mensal Fixo | C31: R$ 750,00 / mes
B32: Ativacoes Digitais | C32: R$ 300,00 / mes (campanhas interativas)
B33: Duracao | C33: 12 meses — Janeiro a Dezembro / 2025
B34: Entregaveis | C34: Splash screen • Banner lateral • Desafio tech mensal • Dashboard
B35: Investimento Total 2025 | C35: R$ 12.600,00 + ativacoes variaveis
B37: PROJECAO MENSAL — 🖥️ FIEBTECH
B38: Mes | C38: Fixo (R$) | D38: Variavel (R$) | E38: Total (R$) | F38: Usuarios | G38: Impressoes | H38: ROI Est.
B39: Jan | C39: 750 | D39: 300 | E39: 1050 | F39: 1200 | G39: 5040 | H39: 9.2x
B40: Fev | C40: 750 | D40: 321 | E40: 1071 | F40: 1272 | G40: 5342 | H40: 9.6x
B41: Mar | C41: 750 | D41: 343 | E41: 1093 | F41: 1348 | G41: 5662 | H41: 10.0x
B42: Abr | C42: 750 | D42: 367 | E42: 1117 | F42: 1429 | G42: 6002 | H42: 10.4x
B43: Mai | C43: 750 | D43: 393 | E43: 1143 | F43: 1514 | G43: 6362 | H43: 10.8x
B44: Jun | C44: 750 | D44: 420 | E44: 1170 | F44: 1605 | G44: 6744 | H44: 11.2x
B45: Jul | C45: 750 | D45: 450 | E45: 1200 | F45: 1702 | G45: 7149 | H45: 11.6x
B46: Ago | C46: 750 | D46: 481 | E46: 1231 | F46: 1804 | G46: 7578 | H46: 12.0x
...
